package net.core.tutorial.medium._24_Exceptions;

/**

 Если метод должен возвращать результат, но в нём внутри есть создание исключения (не в секции try),
 которое пробрасывается дальше в сигнатуре метода, то он не может иметь return в конце.
 После кидания исключения до строки с return даже не дойдёт, поэтому её и не должно быть.
 Нельзя использовать return и в случае, когда исключение кидается в секции try, но нет секции catch (а есть finally),
 и идёт проброс сразу в сигнатуру метода.

 Из секций try, catch и finally можно выйти при помощи return без значения (если метод ничего не возвращает);

 Если метод возвращает значение и в секции try (или в секции catch) имеется return, а также в секции finally
 имеется return, то будет возвращено значение из секции finally.

 Если метод возвращает значение и в секции try или catch имеется return, возвращающий значение, а в секции
 finally переопределяется это значение, то секция finally будет выполнена, но возвращено будет значение,
 которое было кэшировано (запомнено) при return из секции try или catch.

 Если метод возвращает значение и есть секции try-catch-finally, то хотя бы в одной из этих секций должен
 возвращаться return, который сработает по логике работы. Иначе будет ошибка компиляции.

 Секция finally выполняется даже в том случае, если в секции try вылетает исключение, которое не перехватывается
 в catch (например, Error). Или секция catch при этом вообще отсутствует.

 Если метод возвращает значение (в секции try через return возвращается некоторое значение), то сначала
 выполнится секция finally, а уже после значение будет возвращено в точку вызова метода.

 Если в секции try вылетает исключение на некоторой строке кода, после которой идут другие строки кода,
 то после обработки исключения в секции catch курсор не вернётся в секцию try – оставшиеся строки кода
 не будут выполнены.

 Не надо располагать логику после секции catch, если в секции try происходит инициализация/настройка объектов,
 с которыми она работает. Ведь в случае исключения в секции try объекты не будут настроены.
 Такой код, даже если он сам напрямую не может вызвать исключение, лучше располагать в секции try.

 */

public class _05_Exceptions5 {

    public static void main(String[] args) {


    }
}
